<?xml version="1.0" ?>
<!-- =================================================================================== -->
<!-- |    This document was autogenerated by xacro from /home/gene/aidin_dualarm_ws/src/aidin_hand_description/urdf/hand.urdf.xacro | -->
<!-- |    EDITING THIS FILE BY HAND IS NOT RECOMMENDED                                 | -->
<!-- =================================================================================== -->
<robot name="dual_hand">
  <link name="world"/>
  <gazebo reference="world">
    <static>true</static>
  </gazebo>
  <!-- xyz:='0 0 0' rpy:='0 0 0'" -->
  <!-- Joint connecting to parent -->
  <joint name="right_hand_base_joint" type="fixed">
    <parent link="world"/>
    <child link="right_hand_base_link"/>
    <origin rpy="0 0 0" xyz="0 0 0"/>
  </joint>
  <link name="right_hand_base_link">
    <visual>
      <origin rpy="0 0 0" xyz="0 0 0"/>
      <geometry>
        <mesh filename="file:///home/vision/rush_diffusion_policy/searching_grasping_point/(reference)aidin_hand_description/meshes/visual/body_right.STL"/>
      </geometry>
      <material name="">
        <color rgba="0.22353 0.22353 0.22353 1"/>
      </material>
    </visual>
    <collision>
      <origin rpy="0 0 0" xyz="0 0 0"/>
      <geometry>
        <mesh filename="file:///home/vision/rush_diffusion_policy/searching_grasping_point/(reference)aidin_hand_description/meshes/collision/body_right_collision.STL"/>
      </geometry>
    </collision>
    <inertial>
      <origin rpy="0 0 0" xyz="-0.00078195 0.0062725 0.091912"/>
      <mass value="0.96362"/>
      <inertia ixx="0.00040749" ixy="1.8229E-05" ixz="9.0692E-06" iyy="0.00061402" iyz="1.8795E-05" izz="0.00060699"/>
    </inertial>
  </link>
  <link name="right_link1_thumb">
    <inertial>
      <origin rpy="0 0 0" xyz="-2.0882E-10 -0.00032135 0.0045852"/>
      <mass value="0.0035917"/>
      <inertia ixx="4.6019E-08" ixy="3.5431E-15" ixz="-2.4342E-15" iyy="1.4617E-07" iyz="8.4649E-10" izz="1.1542E-07"/>
    </inertial>
    <visual>
      <origin rpy="0 0 0" xyz="0 0 0"/>
      <geometry>
        <mesh filename="file:///home/vision/rush_diffusion_policy/searching_grasping_point/(reference)aidin_hand_description/meshes/visual/link1_thumb.STL"/>
      </geometry>
      <material name="">
        <color rgba="0.77647 0.75686 0.73725 1"/>
      </material>
    </visual>
    <collision>
      <origin rpy="0 0 0" xyz="0 0 0"/>
      <geometry>
        <mesh filename="file:///home/vision/rush_diffusion_policy/searching_grasping_point/(reference)aidin_hand_description/meshes/collision/link1_thumb_collision.STL"/>
      </geometry>
    </collision>
  </link>
  <joint name="right_thumb_joint1" type="revolute">
    <origin rpy="0 0 0.38397" xyz="-0.027991 0.052822 0.07115"/>
    <parent link="right_hand_base_link"/>
    <child link="right_link1_thumb"/>
    <axis xyz="0 0 -1"/>
    <limit effort="10.0" lower="-0.5236" upper="0.5236" velocity="1.5707963"/>
  </joint>
  <link name="right_link2_thumb">
    <inertial>
      <origin rpy="0 0 0" xyz="0.021726 0.016185 -1.2614E-07"/>
      <mass value="0.012509"/>
      <inertia ixx="1.0581E-06" ixy="-7.3153E-07" ixz="-2.0968E-12" iyy="1.1422E-06" iyz="-3.7672E-12" izz="1.6455E-06"/>
    </inertial>
    <visual>
      <origin rpy="0 0 0" xyz="0 0 0"/>
      <geometry>
        <mesh filename="file:///home/vision/rush_diffusion_policy/searching_grasping_point/(reference)aidin_hand_description/meshes/visual/link2_thumb.STL"/>
      </geometry>
      <material name="">
        <color rgba="0.79216 0.81961 0.93333 1"/>
      </material>
    </visual>
    <collision>
      <origin rpy="0 0 0" xyz="0 0 0"/>
      <geometry>
        <mesh filename="file:///home/vision/rush_diffusion_policy/searching_grasping_point/(reference)aidin_hand_description/meshes/collision/link2_thumb_collision.STL"/>
      </geometry>
    </collision>
  </link>
  <joint name="right_thumb_joint2" type="revolute">
    <origin rpy="-1.5708 -1.0703 1.5708" xyz="0 0 0.01035"/>
    <parent link="right_link1_thumb"/>
    <child link="right_link2_thumb"/>
    <axis xyz="0 0 -1"/>
    <limit effort="10.0" lower="0.0" upper="1.0471975" velocity="1.5707963"/>
  </joint>
  <link name="right_link3_thumb">
    <inertial>
      <origin rpy="0 0 0" xyz="-0.010558 -0.012729 -2.0756E-05"/>
      <mass value="0.010399"/>
      <inertia ixx="6.4388E-07" ixy="-4.4349E-07" ixz="4.2316E-10" iyy="7.1496E-07" iyz="-3.9503E-10" izz="1.05E-06"/>
    </inertial>
    <visual>
      <origin rpy="0 0 0" xyz="0 0 0"/>
      <geometry>
        <mesh filename="file:///home/vision/rush_diffusion_policy/searching_grasping_point/(reference)aidin_hand_description/meshes/visual/link3_thumb.STL"/>
      </geometry>
      <material name="">
        <color rgba="0.79216 0.81961 0.93333 1"/>
      </material>
    </visual>
    <collision>
      <origin rpy="0 0 0" xyz="0 0 0"/>
      <geometry>
        <mesh filename="file:///home/vision/rush_diffusion_policy/searching_grasping_point/(reference)aidin_hand_description/meshes/collision/link3_thumb_collision.STL"/>
      </geometry>
    </collision>
  </link>
  <joint name="right_thumb_joint3" type="revolute">
    <origin rpy="0 0 2.9705" xyz="0.037446 0.031946 0"/>
    <parent link="right_link2_thumb"/>
    <child link="right_link3_thumb"/>
    <axis xyz="0 0 -1"/>
    <limit effort="10.0" lower="0.0" upper="1.0471975" velocity="1.5707963"/>
  </joint>
  <link name="right_link4_thumb">
    <inertial>
      <origin rpy="0 0 0" xyz="-0.00045452 0.013538 1.9744E-07"/>
      <mass value="0.009252"/>
      <inertia ixx="6.5738E-07" ixy="1.3358E-07" ixz="-5.4821E-12" iyy="4.3827E-07" iyz="-9.0841E-12" izz="5.8665E-07"/>
    </inertial>
    <visual>
      <origin rpy="0 0 0" xyz="0 0 0"/>
      <geometry>
        <mesh filename="file:///home/vision/rush_diffusion_policy/searching_grasping_point/(reference)aidin_hand_description/meshes/visual/link4_thumb.STL"/>
      </geometry>
      <material name="">
        <color rgba="0.77647 0.75686 0.73725 1"/>
      </material>
    </visual>
    <collision>
      <origin rpy="0 0 0" xyz="0 0 0"/>
      <geometry>
        <mesh filename="file:///home/vision/rush_diffusion_policy/searching_grasping_point/(reference)aidin_hand_description/meshes/collision/link4_thumb_collision.STL"/>
      </geometry>
    </collision>
  </link>
  <joint name="right_thumb_joint4" type="revolute">
    <origin rpy="0 0 2.3512" xyz="-0.02655 -0.029922 0"/>
    <parent link="right_link3_thumb"/>
    <child link="right_link4_thumb"/>
    <axis xyz="0 0 -1"/>
    <mimic joint="right_thumb_joint3" multiplier="1.0" offset="0.0"/>
    <limit effort="10.0" lower="0.0" upper="1.0471975" velocity="1.5707963"/>
  </joint>
  <link name="right_link1_index">
    <inertial>
      <origin rpy="0 0 0" xyz="-2.0882E-10 -0.00032135 0.0045852"/>
      <mass value="0.0035917"/>
      <inertia ixx="4.6019E-08" ixy="3.5431E-15" ixz="-2.4342E-15" iyy="1.4617E-07" iyz="8.4649E-10" izz="1.1542E-07"/>
    </inertial>
    <visual>
      <origin rpy="0 0 0" xyz="0 0 0"/>
      <geometry>
        <mesh filename="file:///home/vision/rush_diffusion_policy/searching_grasping_point/(reference)aidin_hand_description/meshes/visual/link1.STL"/>
      </geometry>
      <material name="">
        <color rgba="0.77647 0.75686 0.73725 1"/>
      </material>
    </visual>
    <collision>
      <origin rpy="0 0 0" xyz="0 0 0"/>
      <geometry>
        <mesh filename="file:///home/vision/rush_diffusion_policy/searching_grasping_point/(reference)aidin_hand_description/meshes/collision/link1_collision.STL"/>
      </geometry>
    </collision>
  </link>
  <joint name="right_index_joint1" type="revolute">
    <origin rpy="1.5708 0 3.1416" xyz="-0.0403 -0.00031 0.17395"/>
    <parent link="right_hand_base_link"/>
    <child link="right_link1_index"/>
    <axis xyz="0 0 -1"/>
    <limit effort="10.0" lower="-0.5236" upper="0.5236" velocity="1.5707963"/>
  </joint>
  <link name="right_link2_index">
    <inertial>
      <origin rpy="0 0 0" xyz="0.020755 0.01379 -1.1732E-06"/>
      <mass value="0.01267"/>
      <inertia ixx="1.0669E-06" ixy="-6.5356E-07" ixz="-8.0013E-11" iyy="1.0065E-06" iyz="-1.1733E-10" izz="1.5287E-06"/>
    </inertial>
    <visual>
      <origin rpy="0 0 0" xyz="0 0 0"/>
      <geometry>
        <mesh filename="file:///home/vision/rush_diffusion_policy/searching_grasping_point/(reference)aidin_hand_description/meshes/visual/link2.STL"/>
      </geometry>
      <material name="">
        <color rgba="0.77647 0.75686 0.73725 1"/>
      </material>
    </visual>
    <collision>
      <origin rpy="0 0 0" xyz="0 0 0"/>
      <geometry>
        <mesh filename="file:///home/vision/rush_diffusion_policy/searching_grasping_point/(reference)aidin_hand_description/meshes/collision/link2_collision.STL"/>
      </geometry>
    </collision>
  </link>
  <joint name="right_index_joint2" type="revolute">
    <origin rpy="-1.5708 -0.78674 1.5708" xyz="0 0 0.01035"/>
    <parent link="right_link1_index"/>
    <child link="right_link2_index"/>
    <axis xyz="0 0 -1"/>
    <limit effort="10.0" lower="0.0" upper="1.5707963" velocity="1.5707963"/>
  </joint>
  <link name="right_link3_index">
    <inertial>
      <origin rpy="0 0 0" xyz="-0.006719 -0.0092478 -2.0377E-08"/>
      <mass value="0.0079187"/>
      <inertia ixx="2.888E-07" ixy="-1.4814E-07" ixz="2.137E-12" iyy="3.6163E-07" iyz="5.3149E-12" izz="4.4045E-07"/>
    </inertial>
    <visual>
      <origin rpy="0 0 0" xyz="0 0 0"/>
      <geometry>
        <mesh filename="file:///home/vision/rush_diffusion_policy/searching_grasping_point/(reference)aidin_hand_description/meshes/visual/link3.STL"/>
      </geometry>
      <material name="">
        <color rgba="0.75294 0.75294 0.75294 1"/>
      </material>
    </visual>
    <collision>
      <origin rpy="0 0 0" xyz="0 0 0"/>
      <geometry>
        <mesh filename="file:///home/vision/rush_diffusion_policy/searching_grasping_point/(reference)aidin_hand_description/meshes/collision/link3_collision.STL"/>
      </geometry>
    </collision>
  </link>
  <joint name="right_index_joint3" type="revolute">
    <origin rpy="0 0 3.0684" xyz="0.034618 0.029118 0"/>
    <parent link="right_link2_index"/>
    <child link="right_link3_index"/>
    <axis xyz="0 0 -1"/>
    <limit effort="10.0" lower="0.0" upper="1.134464" velocity="1.5707963"/>
  </joint>
  <link name="right_link4_index">
    <inertial>
      <origin rpy="0 0 0" xyz="-0.00045453 0.013538 1.9001E-07"/>
      <mass value="0.009252"/>
      <inertia ixx="6.5738E-07" ixy="1.3358E-07" ixz="-5.5427E-12" iyy="4.3827E-07" iyz="-8.5481E-12" izz="5.8665E-07"/>
    </inertial>
    <visual>
      <origin rpy="0 0 0" xyz="0 0 0"/>
      <geometry>
        <mesh filename="file:///home/vision/rush_diffusion_policy/searching_grasping_point/(reference)aidin_hand_description/meshes/visual/link4.STL"/>
      </geometry>
      <material name="">
        <color rgba="0.77647 0.75686 0.73725 1"/>
      </material>
    </visual>
    <collision>
      <origin rpy="0 0 0" xyz="0 0 0"/>
      <geometry>
        <mesh filename="file:///home/vision/rush_diffusion_policy/searching_grasping_point/(reference)aidin_hand_description/meshes/collision/link4_collision.STL"/>
      </geometry>
    </collision>
  </link>
  <joint name="right_index_joint4" type="revolute">
    <origin rpy="0 0 2.5468" xyz="-0.018259 -0.020566 0"/>
    <parent link="right_link3_index"/>
    <child link="right_link4_index"/>
    <axis xyz="0 0 -1"/>
    <mimic joint="right_index_joint3" multiplier="1.0" offset="0.0"/>
    <limit effort="10.0" lower="0.0" upper="1.134464" velocity="1.5707963"/>
  </joint>
  <link name="right_link1_middle">
    <inertial>
      <origin rpy="0 0 0" xyz="-2.0882E-10 -0.00032135 0.0045852"/>
      <mass value="0.0035917"/>
      <inertia ixx="4.6019E-08" ixy="3.5431E-15" ixz="-2.4342E-15" iyy="1.4617E-07" iyz="8.4649E-10" izz="1.1542E-07"/>
    </inertial>
    <visual>
      <origin rpy="0 0 0" xyz="0 0 0"/>
      <geometry>
        <mesh filename="file:///home/vision/rush_diffusion_policy/searching_grasping_point/(reference)aidin_hand_description/meshes/visual/link1.STL"/>
      </geometry>
      <material name="">
        <color rgba="0.77647 0.75686 0.73725 1"/>
      </material>
    </visual>
    <collision>
      <origin rpy="0 0 0" xyz="0 0 0"/>
      <geometry>
        <mesh filename="file:///home/vision/rush_diffusion_policy/searching_grasping_point/(reference)aidin_hand_description/meshes/collision/link1_collision.STL"/>
      </geometry>
    </collision>
  </link>
  <joint name="right_middle_joint1" type="revolute">
    <origin rpy="1.5708 0 3.1416" xyz="-0.0135 -0.00031 0.19145"/>
    <parent link="right_hand_base_link"/>
    <child link="right_link1_middle"/>
    <axis xyz="0 0 -1"/>
    <limit effort="10.0" lower="-0.5236" upper="0.5236" velocity="1.5707963"/>
  </joint>
  <link name="right_link2_middle">
    <inertial>
      <origin rpy="0 0 0" xyz="0.020755 0.01379 -1.1732E-06"/>
      <mass value="0.01267"/>
      <inertia ixx="1.0669E-06" ixy="-6.5356E-07" ixz="-8.0013E-11" iyy="1.0065E-06" iyz="-1.1733E-10" izz="1.5287E-06"/>
    </inertial>
    <visual>
      <origin rpy="0 0 0" xyz="0 0 0"/>
      <geometry>
        <mesh filename="file:///home/vision/rush_diffusion_policy/searching_grasping_point/(reference)aidin_hand_description/meshes/visual/link2.STL"/>
      </geometry>
      <material name="">
        <color rgba="0.77647 0.75686 0.73725 1"/>
      </material>
    </visual>
    <collision>
      <origin rpy="0 0 0" xyz="0 0 0"/>
      <geometry>
        <mesh filename="file:///home/vision/rush_diffusion_policy/searching_grasping_point/(reference)aidin_hand_description/meshes/collision/link2_collision.STL"/>
      </geometry>
    </collision>
  </link>
  <joint name="right_middle_joint2" type="revolute">
    <origin rpy="-1.5708 -0.78674 1.5708" xyz="0 0 0.01035"/>
    <parent link="right_link1_middle"/>
    <child link="right_link2_middle"/>
    <axis xyz="0 0 -1"/>
    <limit effort="10.0" lower="0.0" upper="1.5707963" velocity="1.5707963"/>
  </joint>
  <link name="right_link3_middle">
    <inertial>
      <origin rpy="0 0 0" xyz="-0.006719 -0.0092478 -2.0377E-08"/>
      <mass value="0.0079187"/>
      <inertia ixx="2.888E-07" ixy="-1.4814E-07" ixz="2.137E-12" iyy="3.6163E-07" iyz="5.3149E-12" izz="4.4045E-07"/>
    </inertial>
    <visual>
      <origin rpy="0 0 0" xyz="0 0 0"/>
      <geometry>
        <mesh filename="file:///home/vision/rush_diffusion_policy/searching_grasping_point/(reference)aidin_hand_description/meshes/visual/link3.STL"/>
      </geometry>
      <material name="">
        <color rgba="0.75294 0.75294 0.75294 1"/>
      </material>
    </visual>
    <collision>
      <origin rpy="0 0 0" xyz="0 0 0"/>
      <geometry>
        <mesh filename="file:///home/vision/rush_diffusion_policy/searching_grasping_point/(reference)aidin_hand_description/meshes/collision/link3_collision.STL"/>
      </geometry>
    </collision>
  </link>
  <joint name="right_middle_joint3" type="revolute">
    <origin rpy="0 0 3.0684" xyz="0.034618 0.029118 0"/>
    <parent link="right_link2_middle"/>
    <child link="right_link3_middle"/>
    <axis xyz="0 0 -1"/>
    <limit effort="10.0" lower="0.0" upper="1.134464" velocity="1.5707963"/>
  </joint>
  <link name="right_link4_middle">
    <inertial>
      <origin rpy="0 0 0" xyz="-0.00045453 0.013538 1.9001E-07"/>
      <mass value="0.009252"/>
      <inertia ixx="6.5738E-07" ixy="1.3358E-07" ixz="-5.5427E-12" iyy="4.3827E-07" iyz="-8.5481E-12" izz="5.8665E-07"/>
    </inertial>
    <visual>
      <origin rpy="0 0 0" xyz="0 0 0"/>
      <geometry>
        <mesh filename="file:///home/vision/rush_diffusion_policy/searching_grasping_point/(reference)aidin_hand_description/meshes/visual/link4.STL"/>
      </geometry>
      <material name="">
        <color rgba="0.77647 0.75686 0.73725 1"/>
      </material>
    </visual>
    <collision>
      <origin rpy="0 0 0" xyz="0 0 0"/>
      <geometry>
        <mesh filename="file:///home/vision/rush_diffusion_policy/searching_grasping_point/(reference)aidin_hand_description/meshes/collision/link4_collision.STL"/>
      </geometry>
    </collision>
  </link>
  <joint name="right_middle_joint4" type="revolute">
    <origin rpy="0 0 2.5468" xyz="-0.018259 -0.020566 0"/>
    <parent link="right_link3_middle"/>
    <child link="right_link4_middle"/>
    <axis xyz="0 0 -1"/>
    <mimic joint="right_middle_joint3" multiplier="1.0" offset="0.0"/>
    <limit effort="10.0" lower="0.0" upper="1.134464" velocity="1.5707963"/>
  </joint>
  <link name="right_link1_ring">
    <inertial>
      <origin rpy="0 0 0" xyz="-2.0882E-10 -0.00032135 0.0045852"/>
      <mass value="0.0035917"/>
      <inertia ixx="4.6019E-08" ixy="3.5431E-15" ixz="-2.4342E-15" iyy="1.4617E-07" iyz="8.4649E-10" izz="1.1542E-07"/>
    </inertial>
    <visual>
      <origin rpy="0 0 0" xyz="0 0 0"/>
      <geometry>
        <mesh filename="file:///home/vision/rush_diffusion_policy/searching_grasping_point/(reference)aidin_hand_description/meshes/visual/link1.STL"/>
      </geometry>
      <material name="">
        <color rgba="0.77647 0.75686 0.73725 1"/>
      </material>
    </visual>
    <collision>
      <origin rpy="0 0 0" xyz="0 0 0"/>
      <geometry>
        <mesh filename="file:///home/vision/rush_diffusion_policy/searching_grasping_point/(reference)aidin_hand_description/meshes/collision/link1_collision.STL"/>
      </geometry>
    </collision>
  </link>
  <joint name="right_ring_joint1" type="revolute">
    <origin rpy="1.5708 0 3.1416" xyz="0.0133 -0.00031 0.17395"/>
    <parent link="right_hand_base_link"/>
    <child link="right_link1_ring"/>
    <axis xyz="0 0 -1"/>
    <limit effort="10.0" lower="-0.5236" upper="0.5236" velocity="1.5707963"/>
  </joint>
  <link name="right_link2_ring">
    <inertial>
      <origin rpy="0 0 0" xyz="0.020755 0.01379 -1.1732E-06"/>
      <mass value="0.01267"/>
      <inertia ixx="1.0669E-06" ixy="-6.5356E-07" ixz="-8.0013E-11" iyy="1.0065E-06" iyz="-1.1733E-10" izz="1.5287E-06"/>
    </inertial>
    <visual>
      <origin rpy="0 0 0" xyz="0 0 0"/>
      <geometry>
        <mesh filename="file:///home/vision/rush_diffusion_policy/searching_grasping_point/(reference)aidin_hand_description/meshes/visual/link2.STL"/>
      </geometry>
      <material name="">
        <color rgba="0.77647 0.75686 0.73725 1"/>
      </material>
    </visual>
    <collision>
      <origin rpy="0 0 0" xyz="0 0 0"/>
      <geometry>
        <mesh filename="file:///home/vision/rush_diffusion_policy/searching_grasping_point/(reference)aidin_hand_description/meshes/collision/link2_collision.STL"/>
      </geometry>
    </collision>
  </link>
  <joint name="right_ring_joint2" type="revolute">
    <origin rpy="-1.5708 -0.78674 1.5708" xyz="0 0 0.01035"/>
    <parent link="right_link1_ring"/>
    <child link="right_link2_ring"/>
    <axis xyz="0 0 -1"/>
    <limit effort="10.0" lower="0.0" upper="1.5707963" velocity="1.5707963"/>
  </joint>
  <link name="right_link3_ring">
    <inertial>
      <origin rpy="0 0 0" xyz="-0.006719 -0.0092478 -2.0377E-08"/>
      <mass value="0.0079187"/>
      <inertia ixx="2.888E-07" ixy="-1.4814E-07" ixz="2.137E-12" iyy="3.6163E-07" iyz="5.3149E-12" izz="4.4045E-07"/>
    </inertial>
    <visual>
      <origin rpy="0 0 0" xyz="0 0 0"/>
      <geometry>
        <mesh filename="file:///home/vision/rush_diffusion_policy/searching_grasping_point/(reference)aidin_hand_description/meshes/visual/link3.STL"/>
      </geometry>
      <material name="">
        <color rgba="0.75294 0.75294 0.75294 1"/>
      </material>
    </visual>
    <collision>
      <origin rpy="0 0 0" xyz="0 0 0"/>
      <geometry>
        <mesh filename="file:///home/vision/rush_diffusion_policy/searching_grasping_point/(reference)aidin_hand_description/meshes/collision/link3_collision.STL"/>
      </geometry>
    </collision>
  </link>
  <joint name="right_ring_joint3" type="revolute">
    <origin rpy="0 0 3.0684" xyz="0.034618 0.029118 0"/>
    <parent link="right_link2_ring"/>
    <child link="right_link3_ring"/>
    <axis xyz="0 0 -1"/>
    <limit effort="10.0" lower="0.0" upper="1.134464" velocity="1.5707963"/>
  </joint>
  <link name="right_link4_ring">
    <inertial>
      <origin rpy="0 0 0" xyz="-0.00045453 0.013538 1.9001E-07"/>
      <mass value="0.009252"/>
      <inertia ixx="6.5738E-07" ixy="1.3358E-07" ixz="-5.5427E-12" iyy="4.3827E-07" iyz="-8.5481E-12" izz="5.8665E-07"/>
    </inertial>
    <visual>
      <origin rpy="0 0 0" xyz="0 0 0"/>
      <geometry>
        <mesh filename="file:///home/vision/rush_diffusion_policy/searching_grasping_point/(reference)aidin_hand_description/meshes/visual/link4.STL"/>
      </geometry>
      <material name="">
        <color rgba="0.77647 0.75686 0.73725 1"/>
      </material>
    </visual>
    <collision>
      <origin rpy="0 0 0" xyz="0 0 0"/>
      <geometry>
        <mesh filename="file:///home/vision/rush_diffusion_policy/searching_grasping_point/(reference)aidin_hand_description/meshes/collision/link4_collision.STL"/>
      </geometry>
    </collision>
  </link>
  <joint name="right_ring_joint4" type="revolute">
    <origin rpy="0 0 2.5468" xyz="-0.018259 -0.020566 0"/>
    <parent link="right_link3_ring"/>
    <child link="right_link4_ring"/>
    <axis xyz="0 0 -1"/>
    <mimic joint="right_ring_joint3" multiplier="1.0" offset="0.0"/>
    <limit effort="10.0" lower="0.0" upper="1.134464" velocity="1.5707963"/>
  </joint>
  <link name="right_link1_baby">
    <inertial>
      <origin rpy="0 0 0" xyz="-2.0882E-10 -0.00032135 0.0045852"/>
      <mass value="0.0035917"/>
      <inertia ixx="4.6019E-08" ixy="3.5431E-15" ixz="-2.4342E-15" iyy="1.4617E-07" iyz="8.4649E-10" izz="1.1542E-07"/>
    </inertial>
    <visual>
      <origin rpy="0 0 0" xyz="0 0 0"/>
      <geometry>
        <mesh filename="file:///home/vision/rush_diffusion_policy/searching_grasping_point/(reference)aidin_hand_description/meshes/visual/link1.STL"/>
      </geometry>
      <material name="">
        <color rgba="0.77647 0.75686 0.73725 1"/>
      </material>
    </visual>
    <collision>
      <origin rpy="0 0 0" xyz="0 0 0"/>
      <geometry>
        <mesh filename="file:///home/vision/rush_diffusion_policy/searching_grasping_point/(reference)aidin_hand_description/meshes/collision/link1_collision.STL"/>
      </geometry>
    </collision>
  </link>
  <joint name="right_baby_joint1" type="revolute">
    <origin rpy="1.5708 0 3.1416" xyz="0.0401 -0.00031 0.15845"/>
    <parent link="right_hand_base_link"/>
    <child link="right_link1_baby"/>
    <axis xyz="0 0 -1"/>
    <limit effort="10.0" lower="-0.5236" upper="0.5236" velocity="1.5707963"/>
  </joint>
  <link name="right_link2_baby">
    <inertial>
      <origin rpy="0 0 0" xyz="0.020755 0.01379 -1.1732E-06"/>
      <mass value="0.01267"/>
      <inertia ixx="1.0669E-06" ixy="-6.5356E-07" ixz="-8.0013E-11" iyy="1.0065E-06" iyz="-1.1733E-10" izz="1.5287E-06"/>
    </inertial>
    <visual>
      <origin rpy="0 0 0" xyz="0 0 0"/>
      <geometry>
        <mesh filename="file:///home/vision/rush_diffusion_policy/searching_grasping_point/(reference)aidin_hand_description/meshes/visual/link2.STL"/>
      </geometry>
      <material name="">
        <color rgba="0.77647 0.75686 0.73725 1"/>
      </material>
    </visual>
    <collision>
      <origin rpy="0 0 0" xyz="0 0 0"/>
      <geometry>
        <mesh filename="file:///home/vision/rush_diffusion_policy/searching_grasping_point/(reference)aidin_hand_description/meshes/collision/link2_collision.STL"/>
      </geometry>
    </collision>
  </link>
  <joint name="right_baby_joint2" type="revolute">
    <origin rpy="-1.5708 -0.78674 1.5708" xyz="0 0 0.01035"/>
    <parent link="right_link1_baby"/>
    <child link="right_link2_baby"/>
    <axis xyz="0 0 -1"/>
    <limit effort="10.0" lower="0" upper="1.5707963" velocity="1.5707963"/>
  </joint>
  <link name="right_link3_baby">
    <inertial>
      <origin rpy="0 0 0" xyz="-0.006719 -0.0092478 -2.0377E-08"/>
      <mass value="0.0079187"/>
      <inertia ixx="2.888E-07" ixy="-1.4814E-07" ixz="2.137E-12" iyy="3.6163E-07" iyz="5.3149E-12" izz="4.4045E-07"/>
    </inertial>
    <visual>
      <origin rpy="0 0 0" xyz="0 0 0"/>
      <geometry>
        <mesh filename="file:///home/vision/rush_diffusion_policy/searching_grasping_point/(reference)aidin_hand_description/meshes/visual/link3.STL"/>
      </geometry>
      <material name="">
        <color rgba="0.75294 0.75294 0.75294 1"/>
      </material>
    </visual>
    <collision>
      <origin rpy="0 0 0" xyz="0 0 0"/>
      <geometry>
        <mesh filename="file:///home/vision/rush_diffusion_policy/searching_grasping_point/(reference)aidin_hand_description/meshes/collision/link3_collision.STL"/>
      </geometry>
    </collision>
  </link>
  <joint name="right_baby_joint3" type="revolute">
    <origin rpy="0 0 3.0684" xyz="0.034618 0.029118 0"/>
    <parent link="right_link2_baby"/>
    <child link="right_link3_baby"/>
    <axis xyz="0 0 -1"/>
    <limit effort="10.0" lower="0.0" upper="1.134464" velocity="1.5707963"/>
  </joint>
  <link name="right_link4_baby">
    <inertial>
      <origin rpy="0 0 0" xyz="-0.00045453 0.013538 1.9001E-07"/>
      <mass value="0.009252"/>
      <inertia ixx="6.5738E-07" ixy="1.3358E-07" ixz="-5.5427E-12" iyy="4.3827E-07" iyz="-8.548E-12" izz="5.8665E-07"/>
    </inertial>
    <visual>
      <origin rpy="0 0 0" xyz="0 0 0"/>
      <geometry>
        <mesh filename="file:///home/vision/rush_diffusion_policy/searching_grasping_point/(reference)aidin_hand_description/meshes/visual/link4.STL"/>
      </geometry>
      <material name="">
        <color rgba="0.77647 0.75686 0.73725 1"/>
      </material>
    </visual>
    <collision>
      <origin rpy="0 0 0" xyz="0 0 0"/>
      <geometry>
        <mesh filename="file:///home/vision/rush_diffusion_policy/searching_grasping_point/(reference)aidin_hand_description/meshes/collision/link4_collision.STL"/>
      </geometry>
    </collision>
  </link>
  <joint name="right_baby_joint4" type="revolute">
    <origin rpy="0 0 2.5468" xyz="-0.018259 -0.020566 0"/>
    <parent link="right_link3_baby"/>
    <child link="right_link4_baby"/>
    <axis xyz="0 0 -1"/>
    <mimic joint="right_baby_joint3" multiplier="1.0" offset="0.0"/>
    <limit effort="10.0" lower="0.0" upper="1.134464" velocity="1.5707963"/>
  </joint>
  <!-- xyz:='0 0 0' rpy:='0 0 0'" -->
  <!-- Joint connecting to parent -->
  <joint name="left_hand_base_joint" type="fixed">
    <parent link="world"/>
    <child link="left_hand_base_link"/>
    <origin rpy="0 0 0" xyz="0 0 0"/>
  </joint>
  <link name="left_hand_base_link">
    <visual>
      <origin rpy="0 0 0" xyz="0 0 0"/>
      <geometry>
        <mesh filename="file:///home/vision/rush_diffusion_policy/searching_grasping_point/(reference)aidin_hand_description/meshes/visual/body_left.STL"/>
      </geometry>
      <material name="">
        <color rgba="0.22353 0.22353 0.22353 1"/>
      </material>
    </visual>
    <collision>
      <origin rpy="0 0 0" xyz="0 0 0"/>
      <geometry>
        <mesh filename="file:///home/vision/rush_diffusion_policy/searching_grasping_point/(reference)aidin_hand_description/meshes/collision/body_left_collision.STL"/>
      </geometry>
    </collision>
    <inertial>
      <origin rpy="0 0 0" xyz="-0.00078195 0.0062725 0.091912"/>
      <mass value="0.96362"/>
      <inertia ixx="0.00040749" ixy="-1.8229E-05" ixz="-9.0692E-06" iyy="0.00061402" iyz="1.8795E-05" izz="0.00060699"/>
    </inertial>
  </link>
  <link name="left_link1_thumb">
    <inertial>
      <origin rpy="0 0 0" xyz="0 0.00032135 -0.0045852"/>
      <mass value="0.0035917"/>
      <inertia ixx="4.6019E-08" ixy="3.5431E-15" ixz="-2.4342E-15" iyy="1.4617E-07" iyz="8.4649E-10" izz="1.1542E-07"/>
    </inertial>
    <visual>
      <origin rpy="0 0 0" xyz="0 0 0"/>
      <geometry>
        <mesh filename="file:///home/vision/rush_diffusion_policy/searching_grasping_point/(reference)aidin_hand_description/meshes/visual/link1_thumb.STL"/>
      </geometry>
      <material name="">
        <color rgba="0.77647 0.75686 0.73725 1"/>
      </material>
    </visual>
    <collision>
      <origin rpy="0 0 0" xyz="0 0 0"/>
      <geometry>
        <mesh filename="file:///home/vision/rush_diffusion_policy/searching_grasping_point/(reference)aidin_hand_description/meshes/collision/link1_thumb_collision.STL"/>
      </geometry>
    </collision>
  </link>
  <joint name="left_thumb_joint1" type="revolute">
    <origin rpy="0 0 -0.38397" xyz="0.027991 0.052822 0.07115"/>
    <parent link="left_hand_base_link"/>
    <child link="left_link1_thumb"/>
    <axis xyz="0 0 -1"/>
    <limit effort="10.0" lower="-0.5236" upper="0.5236" velocity="1.5707963"/>
  </joint>
  <link name="left_link2_thumb">
    <inertial>
      <origin rpy="0 0 0" xyz="0.021726 0.016185 -1.2614E-07"/>
      <mass value="0.012509"/>
      <inertia ixx="1.0581E-06" ixy="-7.3153E-07" ixz="-2.0968E-12" iyy="1.1422E-06" iyz="-3.7672E-12" izz="1.6455E-06"/>
    </inertial>
    <visual>
      <origin rpy="0 0 0" xyz="0 0 0"/>
      <geometry>
        <mesh filename="file:///home/vision/rush_diffusion_policy/searching_grasping_point/(reference)aidin_hand_description/meshes/visual/link2_thumb.STL"/>
      </geometry>
      <material name="">
        <color rgba="0.79216 0.81961 0.93333 1"/>
      </material>
    </visual>
    <collision>
      <origin rpy="0 0 0" xyz="0 0 0"/>
      <geometry>
        <mesh filename="file:///home/vision/rush_diffusion_policy/searching_grasping_point/(reference)aidin_hand_description/meshes/collision/link2_thumb_collision.STL"/>
      </geometry>
    </collision>
  </link>
  <joint name="left_thumb_joint2" type="revolute">
    <origin rpy="-1.5708 -1.0703 1.5708" xyz="0 0 0.01035"/>
    <parent link="left_link1_thumb"/>
    <child link="left_link2_thumb"/>
    <axis xyz="0 0 -1"/>
    <limit effort="10.0" lower="0.0" upper="1.0471975" velocity="1.5707963"/>
  </joint>
  <link name="left_link3_thumb">
    <inertial>
      <origin rpy="0 0 0" xyz="-0.010558 -0.012729 -2.0756E-05"/>
      <mass value="0.010399"/>
      <inertia ixx="6.4388E-07" ixy="-4.4349E-07" ixz="4.2316E-10" iyy="7.1496E-07" iyz="-3.9503E-10" izz="1.05E-06"/>
    </inertial>
    <visual>
      <origin rpy="0 0 0" xyz="0 0 0"/>
      <geometry>
        <mesh filename="file:///home/vision/rush_diffusion_policy/searching_grasping_point/(reference)aidin_hand_description/meshes/visual/link3_thumb.STL"/>
      </geometry>
      <material name="">
        <color rgba="0.79216 0.81961 0.93333 1"/>
      </material>
    </visual>
    <collision>
      <origin rpy="0 0 0" xyz="0 0 0"/>
      <geometry>
        <mesh filename="file:///home/vision/rush_diffusion_policy/searching_grasping_point/(reference)aidin_hand_description/meshes/collision/link3_thumb_collision.STL"/>
      </geometry>
    </collision>
  </link>
  <joint name="left_thumb_joint3" type="revolute">
    <origin rpy="0 0 2.9705" xyz="0.037446 0.031946 0"/>
    <parent link="left_link2_thumb"/>
    <child link="left_link3_thumb"/>
    <axis xyz="0 0 -1"/>
    <limit effort="10.0" lower="0.0" upper="1.0471975" velocity="1.5707963"/>
  </joint>
  <link name="left_link4_thumb">
    <inertial>
      <origin rpy="0 0 0" xyz="-0.00045452 0.013538 1.9744E-07"/>
      <mass value="0.009252"/>
      <inertia ixx="6.5738E-07" ixy="1.3358E-07" ixz="-5.4821E-12" iyy="4.3827E-07" iyz="-9.0841E-12" izz="5.8665E-07"/>
    </inertial>
    <visual>
      <origin rpy="0 0 0" xyz="0 0 0"/>
      <geometry>
        <mesh filename="file:///home/vision/rush_diffusion_policy/searching_grasping_point/(reference)aidin_hand_description/meshes/visual/link4_thumb.STL"/>
      </geometry>
      <material name="">
        <color rgba="0.77647 0.75686 0.73725 1"/>
      </material>
    </visual>
    <collision>
      <origin rpy="0 0 0" xyz="0 0 0"/>
      <geometry>
        <mesh filename="file:///home/vision/rush_diffusion_policy/searching_grasping_point/(reference)aidin_hand_description/meshes/collision/link4_thumb_collision.STL"/>
      </geometry>
    </collision>
  </link>
  <joint name="left_thumb_joint4" type="revolute">
    <origin rpy="0 0 2.3512" xyz="-0.02655 -0.029922 0"/>
    <parent link="left_link3_thumb"/>
    <child link="left_link4_thumb"/>
    <axis xyz="0 0 -1"/>
    <mimic joint="left_thumb_joint3" multiplier="1.0" offset="0.0"/>
    <limit effort="10.0" lower="0.0" upper="1.0471975" velocity="1.5707963"/>
  </joint>
  <link name="left_link1_index">
    <inertial>
      <origin rpy="0 0 0" xyz="-2.0882E-10 -0.00032135 0.0045852"/>
      <mass value="0.0035917"/>
      <inertia ixx="4.6019E-08" ixy="3.5431E-15" ixz="-2.4342E-15" iyy="1.4617E-07" iyz="8.4649E-10" izz="1.1542E-07"/>
    </inertial>
    <visual>
      <origin rpy="0 0 0" xyz="0 0 0"/>
      <geometry>
        <mesh filename="file:///home/vision/rush_diffusion_policy/searching_grasping_point/(reference)aidin_hand_description/meshes/visual/link1.STL"/>
      </geometry>
      <material name="">
        <color rgba="0.77647 0.75686 0.73725 1"/>
      </material>
    </visual>
    <collision>
      <origin rpy="0 0 0" xyz="0 0 0"/>
      <geometry>
        <mesh filename="file:///home/vision/rush_diffusion_policy/searching_grasping_point/(reference)aidin_hand_description/meshes/collision/link1_collision.STL"/>
      </geometry>
    </collision>
  </link>
  <joint name="left_index_joint1" type="revolute">
    <origin rpy="1.5708 0 3.1416" xyz="0.0403 -0.00031 0.17395"/>
    <parent link="left_hand_base_link"/>
    <child link="left_link1_index"/>
    <axis xyz="0 0 -1"/>
    <limit effort="10.0" lower="-0.5236" upper="0.5236" velocity="1.5707963"/>
  </joint>
  <link name="left_link2_index">
    <inertial>
      <origin rpy="0 0 0" xyz="0.020755 0.01379 -1.1732E-06"/>
      <mass value="0.01267"/>
      <inertia ixx="1.0669E-06" ixy="-6.5356E-07" ixz="-8.0013E-11" iyy="1.0065E-06" iyz="-1.1733E-10" izz="1.5287E-06"/>
    </inertial>
    <visual>
      <origin rpy="0 0 0" xyz="0 0 0"/>
      <geometry>
        <mesh filename="file:///home/vision/rush_diffusion_policy/searching_grasping_point/(reference)aidin_hand_description/meshes/visual/link2.STL"/>
      </geometry>
      <material name="">
        <color rgba="0.77647 0.75686 0.73725 1"/>
      </material>
    </visual>
    <collision>
      <origin rpy="0 0 0" xyz="0 0 0"/>
      <geometry>
        <mesh filename="file:///home/vision/rush_diffusion_policy/searching_grasping_point/(reference)aidin_hand_description/meshes/collision/link2_collision.STL"/>
      </geometry>
    </collision>
  </link>
  <joint name="left_index_joint2" type="revolute">
    <origin rpy="-1.5708 -0.78674 1.5708" xyz="0 0 0.01035"/>
    <parent link="left_link1_index"/>
    <child link="left_link2_index"/>
    <axis xyz="0 0 -1"/>
    <limit effort="10.0" lower="0.0" upper="1.5707963" velocity="1.5707963"/>
  </joint>
  <link name="left_link3_index">
    <inertial>
      <origin rpy="0 0 0" xyz="-0.006719 -0.0092478 -2.0377E-08"/>
      <mass value="0.0079187"/>
      <inertia ixx="2.888E-07" ixy="-1.4814E-07" ixz="2.137E-12" iyy="3.6163E-07" iyz="5.3149E-12" izz="4.4045E-07"/>
    </inertial>
    <visual>
      <origin rpy="0 0 0" xyz="0 0 0"/>
      <geometry>
        <mesh filename="file:///home/vision/rush_diffusion_policy/searching_grasping_point/(reference)aidin_hand_description/meshes/visual/link3.STL"/>
      </geometry>
      <material name="">
        <color rgba="0.75294 0.75294 0.75294 1"/>
      </material>
    </visual>
    <collision>
      <origin rpy="0 0 0" xyz="0 0 0"/>
      <geometry>
        <mesh filename="file:///home/vision/rush_diffusion_policy/searching_grasping_point/(reference)aidin_hand_description/meshes/collision/link3_collision.STL"/>
      </geometry>
    </collision>
  </link>
  <joint name="left_index_joint3" type="revolute">
    <origin rpy="0 0 3.0684" xyz="0.034618 0.029118 0"/>
    <parent link="left_link2_index"/>
    <child link="left_link3_index"/>
    <axis xyz="0 0 -1"/>
    <limit effort="10.0" lower="0.0" upper="1.134464" velocity="1.5707963"/>
  </joint>
  <link name="left_link4_index">
    <inertial>
      <origin rpy="0 0 0" xyz="-0.00045453 0.013538 1.9001E-07"/>
      <mass value="0.009252"/>
      <inertia ixx="6.5738E-07" ixy="1.3358E-07" ixz="-5.5427E-12" iyy="4.3827E-07" iyz="-8.5481E-12" izz="5.8665E-07"/>
    </inertial>
    <visual>
      <origin rpy="0 0 0" xyz="0 0 0"/>
      <geometry>
        <mesh filename="file:///home/vision/rush_diffusion_policy/searching_grasping_point/(reference)aidin_hand_description/meshes/visual/link4.STL"/>
      </geometry>
      <material name="">
        <color rgba="0.77647 0.75686 0.73725 1"/>
      </material>
    </visual>
    <collision>
      <origin rpy="0 0 0" xyz="0 0 0"/>
      <geometry>
        <mesh filename="file:///home/vision/rush_diffusion_policy/searching_grasping_point/(reference)aidin_hand_description/meshes/collision/link4_collision.STL"/>
      </geometry>
    </collision>
  </link>
  <joint name="left_index_joint4" type="revolute">
    <origin rpy="0 0 2.5468" xyz="-0.018259 -0.020566 0"/>
    <parent link="left_link3_index"/>
    <child link="left_link4_index"/>
    <axis xyz="0 0 -1"/>
    <mimic joint="left_index_joint3" multiplier="1.0" offset="0.0"/>
    <limit effort="10.0" lower="0.0" upper="1.134464" velocity="1.5707963"/>
  </joint>
  <link name="left_link1_middle">
    <inertial>
      <origin rpy="0 0 0" xyz="-2.0882E-10 -0.00032135 0.0045852"/>
      <mass value="0.0035917"/>
      <inertia ixx="4.6019E-08" ixy="3.5431E-15" ixz="-2.4342E-15" iyy="1.4617E-07" iyz="8.4649E-10" izz="1.1542E-07"/>
    </inertial>
    <visual>
      <origin rpy="0 0 0" xyz="0 0 0"/>
      <geometry>
        <mesh filename="file:///home/vision/rush_diffusion_policy/searching_grasping_point/(reference)aidin_hand_description/meshes/visual/link1.STL"/>
      </geometry>
      <material name="">
        <color rgba="0.77647 0.75686 0.73725 1"/>
      </material>
    </visual>
    <collision>
      <origin rpy="0 0 0" xyz="0 0 0"/>
      <geometry>
        <mesh filename="file:///home/vision/rush_diffusion_policy/searching_grasping_point/(reference)aidin_hand_description/meshes/collision/link1_collision.STL"/>
      </geometry>
    </collision>
  </link>
  <joint name="left_middle_joint1" type="revolute">
    <origin rpy="1.5708 0 3.1416" xyz="0.0135 -0.00031 0.19145"/>
    <parent link="left_hand_base_link"/>
    <child link="left_link1_middle"/>
    <axis xyz="0 0 -1"/>
    <limit effort="10.0" lower="-0.5236" upper="0.5236" velocity="1.5707963"/>
  </joint>
  <link name="left_link2_middle">
    <inertial>
      <origin rpy="0 0 0" xyz="0.020755 0.01379 -1.1732E-06"/>
      <mass value="0.01267"/>
      <inertia ixx="1.0669E-06" ixy="-6.5356E-07" ixz="-8.0013E-11" iyy="1.0065E-06" iyz="-1.1733E-10" izz="1.5287E-06"/>
    </inertial>
    <visual>
      <origin rpy="0 0 0" xyz="0 0 0"/>
      <geometry>
        <mesh filename="file:///home/vision/rush_diffusion_policy/searching_grasping_point/(reference)aidin_hand_description/meshes/visual/link2.STL"/>
      </geometry>
      <material name="">
        <color rgba="0.77647 0.75686 0.73725 1"/>
      </material>
    </visual>
    <collision>
      <origin rpy="0 0 0" xyz="0 0 0"/>
      <geometry>
        <mesh filename="file:///home/vision/rush_diffusion_policy/searching_grasping_point/(reference)aidin_hand_description/meshes/collision/link2_collision.STL"/>
      </geometry>
    </collision>
  </link>
  <joint name="left_middle_joint2" type="revolute">
    <origin rpy="-1.5708 -0.78674 1.5708" xyz="0 0 0.01035"/>
    <parent link="left_link1_middle"/>
    <child link="left_link2_middle"/>
    <axis xyz="0 0 -1"/>
    <limit effort="10.0" lower="0.0" upper="1.5707963" velocity="1.5707963"/>
  </joint>
  <link name="left_link3_middle">
    <inertial>
      <origin rpy="0 0 0" xyz="-0.006719 -0.0092478 -2.0377E-08"/>
      <mass value="0.0079187"/>
      <inertia ixx="2.888E-07" ixy="-1.4814E-07" ixz="2.137E-12" iyy="3.6163E-07" iyz="5.3149E-12" izz="4.4045E-07"/>
    </inertial>
    <visual>
      <origin rpy="0 0 0" xyz="0 0 0"/>
      <geometry>
        <mesh filename="file:///home/vision/rush_diffusion_policy/searching_grasping_point/(reference)aidin_hand_description/meshes/visual/link3.STL"/>
      </geometry>
      <material name="">
        <color rgba="0.75294 0.75294 0.75294 1"/>
      </material>
    </visual>
    <collision>
      <origin rpy="0 0 0" xyz="0 0 0"/>
      <geometry>
        <mesh filename="file:///home/vision/rush_diffusion_policy/searching_grasping_point/(reference)aidin_hand_description/meshes/collision/link3_collision.STL"/>
      </geometry>
    </collision>
  </link>
  <joint name="left_middle_joint3" type="revolute">
    <origin rpy="0 0 3.0684" xyz="0.034618 0.029118 0"/>
    <parent link="left_link2_middle"/>
    <child link="left_link3_middle"/>
    <axis xyz="0 0 -1"/>
    <limit effort="10.0" lower="0.0" upper="1.134464" velocity="1.5707963"/>
  </joint>
  <link name="left_link4_middle">
    <inertial>
      <origin rpy="0 0 0" xyz="-0.00045453 0.013538 1.9001E-07"/>
      <mass value="0.009252"/>
      <inertia ixx="6.5738E-07" ixy="1.3358E-07" ixz="-5.5427E-12" iyy="4.3827E-07" iyz="-8.5481E-12" izz="5.8665E-07"/>
    </inertial>
    <visual>
      <origin rpy="0 0 0" xyz="0 0 0"/>
      <geometry>
        <mesh filename="file:///home/vision/rush_diffusion_policy/searching_grasping_point/(reference)aidin_hand_description/meshes/visual/link4.STL"/>
      </geometry>
      <material name="">
        <color rgba="0.77647 0.75686 0.73725 1"/>
      </material>
    </visual>
    <collision>
      <origin rpy="0 0 0" xyz="0 0 0"/>
      <geometry>
        <mesh filename="file:///home/vision/rush_diffusion_policy/searching_grasping_point/(reference)aidin_hand_description/meshes/collision/link4_collision.STL"/>
      </geometry>
    </collision>
  </link>
  <joint name="left_middle_joint4" type="revolute">
    <origin rpy="0 0 2.5468" xyz="-0.018259 -0.020566 0"/>
    <parent link="left_link3_middle"/>
    <child link="left_link4_middle"/>
    <axis xyz="0 0 -1"/>
    <mimic joint="left_middle_joint3" multiplier="1.0" offset="0.0"/>
    <limit effort="10.0" lower="0.0" upper="1.134464" velocity="1.5707963"/>
  </joint>
  <link name="left_link1_ring">
    <inertial>
      <origin rpy="0 0 0" xyz="-2.0882E-10 -0.00032135 0.0045852"/>
      <mass value="0.0035917"/>
      <inertia ixx="4.6019E-08" ixy="3.5431E-15" ixz="-2.4342E-15" iyy="1.4617E-07" iyz="8.4649E-10" izz="1.1542E-07"/>
    </inertial>
    <visual>
      <origin rpy="0 0 0" xyz="0 0 0"/>
      <geometry>
        <mesh filename="file:///home/vision/rush_diffusion_policy/searching_grasping_point/(reference)aidin_hand_description/meshes/visual/link1.STL"/>
      </geometry>
      <material name="">
        <color rgba="0.77647 0.75686 0.73725 1"/>
      </material>
    </visual>
    <collision>
      <origin rpy="0 0 0" xyz="0 0 0"/>
      <geometry>
        <mesh filename="file:///home/vision/rush_diffusion_policy/searching_grasping_point/(reference)aidin_hand_description/meshes/collision/link1_collision.STL"/>
      </geometry>
    </collision>
  </link>
  <joint name="left_ring_joint1" type="revolute">
    <origin rpy="1.5708 0 3.1416" xyz="-0.0133 -0.00031 0.17395"/>
    <parent link="left_hand_base_link"/>
    <child link="left_link1_ring"/>
    <axis xyz="0 0 -1"/>
    <limit effort="10.0" lower="-0.5236" upper="0.5236" velocity="1.5707963"/>
  </joint>
  <link name="left_link2_ring">
    <inertial>
      <origin rpy="0 0 0" xyz="0.020755 0.01379 -1.1732E-06"/>
      <mass value="0.01267"/>
      <inertia ixx="1.0669E-06" ixy="-6.5356E-07" ixz="-8.0013E-11" iyy="1.0065E-06" iyz="-1.1733E-10" izz="1.5287E-06"/>
    </inertial>
    <visual>
      <origin rpy="0 0 0" xyz="0 0 0"/>
      <geometry>
        <mesh filename="file:///home/vision/rush_diffusion_policy/searching_grasping_point/(reference)aidin_hand_description/meshes/visual/link2.STL"/>
      </geometry>
      <material name="">
        <color rgba="0.77647 0.75686 0.73725 1"/>
      </material>
    </visual>
    <collision>
      <origin rpy="0 0 0" xyz="0 0 0"/>
      <geometry>
        <mesh filename="file:///home/vision/rush_diffusion_policy/searching_grasping_point/(reference)aidin_hand_description/meshes/collision/link2_collision.STL"/>
      </geometry>
    </collision>
  </link>
  <joint name="left_ring_joint2" type="revolute">
    <origin rpy="-1.5708 -0.78674 1.5708" xyz="0 0 0.01035"/>
    <parent link="left_link1_ring"/>
    <child link="left_link2_ring"/>
    <axis xyz="0 0 -1"/>
    <limit effort="10.0" lower="0.0" upper="1.5707963" velocity="1.5707963"/>
  </joint>
  <link name="left_link3_ring">
    <inertial>
      <origin rpy="0 0 0" xyz="-0.006719 -0.0092478 -2.0377E-08"/>
      <mass value="0.0079187"/>
      <inertia ixx="2.888E-07" ixy="-1.4814E-07" ixz="2.137E-12" iyy="3.6163E-07" iyz="5.3149E-12" izz="4.4045E-07"/>
    </inertial>
    <visual>
      <origin rpy="0 0 0" xyz="0 0 0"/>
      <geometry>
        <mesh filename="file:///home/vision/rush_diffusion_policy/searching_grasping_point/(reference)aidin_hand_description/meshes/visual/link3.STL"/>
      </geometry>
      <material name="">
        <color rgba="0.75294 0.75294 0.75294 1"/>
      </material>
    </visual>
    <collision>
      <origin rpy="0 0 0" xyz="0 0 0"/>
      <geometry>
        <mesh filename="file:///home/vision/rush_diffusion_policy/searching_grasping_point/(reference)aidin_hand_description/meshes/collision/link3_collision.STL"/>
      </geometry>
    </collision>
  </link>
  <joint name="left_ring_joint3" type="revolute">
    <origin rpy="0 0 3.0684" xyz="0.034618 0.029118 0"/>
    <parent link="left_link2_ring"/>
    <child link="left_link3_ring"/>
    <axis xyz="0 0 -1"/>
    <limit effort="10.0" lower="0.0" upper="1.134464" velocity="1.5707963"/>
  </joint>
  <link name="left_link4_ring">
    <inertial>
      <origin rpy="0 0 0" xyz="-0.00045453 0.013538 1.9001E-07"/>
      <mass value="0.009252"/>
      <inertia ixx="6.5738E-07" ixy="1.3358E-07" ixz="-5.5427E-12" iyy="4.3827E-07" iyz="-8.5481E-12" izz="5.8665E-07"/>
    </inertial>
    <visual>
      <origin rpy="0 0 0" xyz="0 0 0"/>
      <geometry>
        <mesh filename="file:///home/vision/rush_diffusion_policy/searching_grasping_point/(reference)aidin_hand_description/meshes/visual/link4.STL"/>
      </geometry>
      <material name="">
        <color rgba="0.77647 0.75686 0.73725 1"/>
      </material>
    </visual>
    <collision>
      <origin rpy="0 0 0" xyz="0 0 0"/>
      <geometry>
        <mesh filename="file:///home/vision/rush_diffusion_policy/searching_grasping_point/(reference)aidin_hand_description/meshes/collision/link4_collision.STL"/>
      </geometry>
    </collision>
  </link>
  <joint name="left_ring_joint4" type="revolute">
    <origin rpy="0 0 2.5468" xyz="-0.018259 -0.020566 0"/>
    <parent link="left_link3_ring"/>
    <child link="left_link4_ring"/>
    <axis xyz="0 0 -1"/>
    <mimic joint="left_ring_joint3" multiplier="1.0" offset="0.0"/>
    <limit effort="10.0" lower="0.0" upper="1.134464" velocity="1.5707963"/>
  </joint>
  <link name="left_link1_baby">
    <inertial>
      <origin rpy="0 0 0" xyz="-2.0882E-10 -0.00032135 0.0045852"/>
      <mass value="0.0035917"/>
      <inertia ixx="4.6019E-08" ixy="3.5431E-15" ixz="-2.4342E-15" iyy="1.4617E-07" iyz="8.4649E-10" izz="1.1542E-07"/>
    </inertial>
    <visual>
      <origin rpy="0 0 0" xyz="0 0 0"/>
      <geometry>
        <mesh filename="file:///home/vision/rush_diffusion_policy/searching_grasping_point/(reference)aidin_hand_description/meshes/visual/link1.STL"/>
      </geometry>
      <material name="">
        <color rgba="0.77647 0.75686 0.73725 1"/>
      </material>
    </visual>
    <collision>
      <origin rpy="0 0 0" xyz="0 0 0"/>
      <geometry>
        <mesh filename="file:///home/vision/rush_diffusion_policy/searching_grasping_point/(reference)aidin_hand_description/meshes/collision/link1_collision.STL"/>
      </geometry>
    </collision>
  </link>
  <joint name="left_baby_joint1" type="revolute">
    <origin rpy="1.5708 0 3.1416" xyz="-0.0401 -0.00031 0.15845"/>
    <parent link="left_hand_base_link"/>
    <child link="left_link1_baby"/>
    <axis xyz="0 0 -1"/>
    <limit effort="10.0" lower="-0.5236" upper="0.5236" velocity="1.5707963"/>
  </joint>
  <link name="left_link2_baby">
    <inertial>
      <origin rpy="0 0 0" xyz="0.020755 0.01379 -1.1732E-06"/>
      <mass value="0.01267"/>
      <inertia ixx="1.0669E-06" ixy="-6.5356E-07" ixz="-8.0013E-11" iyy="1.0065E-06" iyz="-1.1733E-10" izz="1.5287E-06"/>
    </inertial>
    <visual>
      <origin rpy="0 0 0" xyz="0 0 0"/>
      <geometry>
        <mesh filename="file:///home/vision/rush_diffusion_policy/searching_grasping_point/(reference)aidin_hand_description/meshes/visual/link2.STL"/>
      </geometry>
      <material name="">
        <color rgba="0.77647 0.75686 0.73725 1"/>
      </material>
    </visual>
    <collision>
      <origin rpy="0 0 0" xyz="0 0 0"/>
      <geometry>
        <mesh filename="file:///home/vision/rush_diffusion_policy/searching_grasping_point/(reference)aidin_hand_description/meshes/collision/link2_collision.STL"/>
      </geometry>
    </collision>
  </link>
  <joint name="left_baby_joint2" type="revolute">
    <origin rpy="-1.5708 -0.78674 1.5708" xyz="0 0 0.01035"/>
    <parent link="left_link1_baby"/>
    <child link="left_link2_baby"/>
    <axis xyz="0 0 -1"/>
    <limit effort="10.0" lower="0" upper="1.5707963" velocity="1.5707963"/>
  </joint>
  <link name="left_link3_baby">
    <inertial>
      <origin rpy="0 0 0" xyz="-0.006719 -0.0092478 -2.0377E-08"/>
      <mass value="0.0079187"/>
      <inertia ixx="2.888E-07" ixy="-1.4814E-07" ixz="2.137E-12" iyy="3.6163E-07" iyz="5.3149E-12" izz="4.4045E-07"/>
    </inertial>
    <visual>
      <origin rpy="0 0 0" xyz="0 0 0"/>
      <geometry>
        <mesh filename="file:///home/vision/rush_diffusion_policy/searching_grasping_point/(reference)aidin_hand_description/meshes/visual/link3.STL"/>
      </geometry>
      <material name="">
        <color rgba="0.75294 0.75294 0.75294 1"/>
      </material>
    </visual>
    <collision>
      <origin rpy="0 0 0" xyz="0 0 0"/>
      <geometry>
        <mesh filename="file:///home/vision/rush_diffusion_policy/searching_grasping_point/(reference)aidin_hand_description/meshes/collision/link3_collision.STL"/>
      </geometry>
    </collision>
  </link>
  <joint name="left_baby_joint3" type="revolute">
    <origin rpy="0 0 3.0684" xyz="0.034618 0.029118 0"/>
    <parent link="left_link2_baby"/>
    <child link="left_link3_baby"/>
    <axis xyz="0 0 -1"/>
    <limit effort="10.0" lower="0.0" upper="1.134464" velocity="1.5707963"/>
  </joint>
  <link name="left_link4_baby">
    <inertial>
      <origin rpy="0 0 0" xyz="-0.00045453 0.013538 1.9001E-07"/>
      <mass value="0.009252"/>
      <inertia ixx="6.5738E-07" ixy="1.3358E-07" ixz="-5.5427E-12" iyy="4.3827E-07" iyz="-8.548E-12" izz="5.8665E-07"/>
    </inertial>
    <visual>
      <origin rpy="0 0 0" xyz="0 0 0"/>
      <geometry>
        <mesh filename="file:///home/vision/rush_diffusion_policy/searching_grasping_point/(reference)aidin_hand_description/meshes/visual/link4.STL"/>
      </geometry>
      <material name="">
        <color rgba="0.77647 0.75686 0.73725 1"/>
      </material>
    </visual>
    <collision>
      <origin rpy="0 0 0" xyz="0 0 0"/>
      <geometry>
        <mesh filename="file:///home/vision/rush_diffusion_policy/searching_grasping_point/(reference)aidin_hand_description/meshes/collision/link4_collision.STL"/>
      </geometry>
    </collision>
  </link>
  <joint name="left_baby_joint4" type="revolute">
    <origin rpy="0 0 2.5468" xyz="-0.018259 -0.020566 0"/>
    <parent link="left_link3_baby"/>
    <child link="left_link4_baby"/>
    <axis xyz="0 0 -1"/>
    <mimic joint="left_baby_joint3" multiplier="1.0" offset="0.0"/>
    <limit effort="10.0" lower="0.0" upper="1.134464" velocity="1.5707963"/>
  </joint>
  <ros2_control name="hand" type="system">
    <hardware>
      <plugin>aidin_hand_hardware/EthercatDriver</plugin>
      <param name="master_id">0</param>
      <param name="control_frequency">1000</param>
    </hardware>
    <joint name="left_thumb_encoder1">
      <command_interface name="axis1/position"/>
      <command_interface name="axis1/velocity"/>
      <command_interface name="axis1/effort"/>
      <command_interface name="axis1/maximum_effort"/>
      <command_interface name="axis1/control_word"/>
      <command_interface name="axis1/mode_of_operation"/>
      <state_interface name="axis1/internal_position"/>
      <state_interface name="axis1/position"/>
      <state_interface name="axis1/velocity"/>
      <state_interface name="axis1/effort"/>
      <state_interface name="axis1/status_word"/>
      <state_interface name="axis1/error_code"/>
      <state_interface name="axis1/force_x"/>
      <state_interface name="axis1/force_y"/>
      <state_interface name="axis1/force_z"/>
      <ec_module name="ec_module">
        <plugin>ethercat_generic_plugins/GenericEcSlave</plugin>
        <param name="alias">0</param>
        <param name="position">0</param>
        <param name="mode_of_operation">8</param>
        <param name="slave_config">/home/gene/aidin_dualarm_ws/install/aidin_hand_description/share/aidin_hand_description/config/welcon_slave.yaml</param>
      </ec_module>
    </joint>
    <joint name="left_thumb_encoder2">
      <command_interface name="axis2/position"/>
      <command_interface name="axis2/velocity"/>
      <command_interface name="axis2/effort"/>
      <command_interface name="axis2/maximum_effort"/>
      <command_interface name="axis2/control_word"/>
      <command_interface name="axis2/mode_of_operation"/>
      <state_interface name="axis2/internal_position"/>
      <state_interface name="axis2/position"/>
      <state_interface name="axis2/velocity"/>
      <state_interface name="axis2/effort"/>
      <state_interface name="axis2/status_word"/>
      <state_interface name="axis2/error_code"/>
      <state_interface name="axis2/torque_x"/>
      <state_interface name="axis2/torque_y"/>
      <state_interface name="axis2/torque_z"/>
      <ec_module name="ec_module">
        <plugin>ethercat_generic_plugins/GenericEcSlave</plugin>
        <param name="alias">0</param>
        <param name="position">0</param>
        <param name="mode_of_operation">8</param>
        <param name="slave_config">/home/gene/aidin_dualarm_ws/install/aidin_hand_description/share/aidin_hand_description/config/welcon_slave.yaml</param>
      </ec_module>
    </joint>
    <joint name="left_thumb_encoder3">
      <command_interface name="axis3/position"/>
      <command_interface name="axis3/velocity"/>
      <command_interface name="axis3/effort"/>
      <command_interface name="axis3/maximum_effort"/>
      <command_interface name="axis3/control_word"/>
      <command_interface name="axis3/mode_of_operation"/>
      <state_interface name="axis3/internal_position"/>
      <state_interface name="axis3/position"/>
      <state_interface name="axis3/velocity"/>
      <state_interface name="axis3/effort"/>
      <state_interface name="axis3/status_word"/>
      <state_interface name="axis3/error_code"/>
      <ec_module name="ec_module">
        <plugin>ethercat_generic_plugins/GenericEcSlave</plugin>
        <param name="alias">0</param>
        <param name="position">0</param>
        <param name="mode_of_operation">8</param>
        <param name="slave_config">/home/gene/aidin_dualarm_ws/install/aidin_hand_description/share/aidin_hand_description/config/welcon_slave.yaml</param>
      </ec_module>
    </joint>
    <joint name="left_index_encoder1">
      <command_interface name="axis1/position"/>
      <command_interface name="axis1/velocity"/>
      <command_interface name="axis1/effort"/>
      <command_interface name="axis1/maximum_effort"/>
      <command_interface name="axis1/control_word"/>
      <command_interface name="axis1/mode_of_operation"/>
      <state_interface name="axis1/internal_position"/>
      <state_interface name="axis1/position"/>
      <state_interface name="axis1/velocity"/>
      <state_interface name="axis1/effort"/>
      <state_interface name="axis1/status_word"/>
      <state_interface name="axis1/error_code"/>
      <state_interface name="axis1/force_x"/>
      <state_interface name="axis1/force_y"/>
      <state_interface name="axis1/force_z"/>
      <ec_module name="ec_module">
        <plugin>ethercat_generic_plugins/GenericEcSlave</plugin>
        <param name="alias">0</param>
        <param name="position">1</param>
        <param name="mode_of_operation">8</param>
        <param name="slave_config">/home/gene/aidin_dualarm_ws/install/aidin_hand_description/share/aidin_hand_description/config/welcon_slave.yaml</param>
      </ec_module>
    </joint>
    <joint name="left_index_encoder2">
      <command_interface name="axis2/position"/>
      <command_interface name="axis2/velocity"/>
      <command_interface name="axis2/effort"/>
      <command_interface name="axis2/maximum_effort"/>
      <command_interface name="axis2/control_word"/>
      <command_interface name="axis2/mode_of_operation"/>
      <state_interface name="axis2/internal_position"/>
      <state_interface name="axis2/position"/>
      <state_interface name="axis2/velocity"/>
      <state_interface name="axis2/effort"/>
      <state_interface name="axis2/status_word"/>
      <state_interface name="axis2/error_code"/>
      <state_interface name="axis2/torque_x"/>
      <state_interface name="axis2/torque_y"/>
      <state_interface name="axis2/torque_z"/>
      <ec_module name="ec_module">
        <plugin>ethercat_generic_plugins/GenericEcSlave</plugin>
        <param name="alias">0</param>
        <param name="position">1</param>
        <param name="mode_of_operation">8</param>
        <param name="slave_config">/home/gene/aidin_dualarm_ws/install/aidin_hand_description/share/aidin_hand_description/config/welcon_slave.yaml</param>
      </ec_module>
    </joint>
    <joint name="left_index_encoder3">
      <command_interface name="axis3/position"/>
      <command_interface name="axis3/velocity"/>
      <command_interface name="axis3/effort"/>
      <command_interface name="axis3/maximum_effort"/>
      <command_interface name="axis3/control_word"/>
      <command_interface name="axis3/mode_of_operation"/>
      <state_interface name="axis3/internal_position"/>
      <state_interface name="axis3/position"/>
      <state_interface name="axis3/velocity"/>
      <state_interface name="axis3/effort"/>
      <state_interface name="axis3/status_word"/>
      <state_interface name="axis3/error_code"/>
      <ec_module name="ec_module">
        <plugin>ethercat_generic_plugins/GenericEcSlave</plugin>
        <param name="alias">0</param>
        <param name="position">1</param>
        <param name="mode_of_operation">8</param>
        <param name="slave_config">/home/gene/aidin_dualarm_ws/install/aidin_hand_description/share/aidin_hand_description/config/welcon_slave.yaml</param>
      </ec_module>
    </joint>
    <joint name="left_middle_encoder1">
      <command_interface name="axis1/position"/>
      <command_interface name="axis1/velocity"/>
      <command_interface name="axis1/effort"/>
      <command_interface name="axis1/maximum_effort"/>
      <command_interface name="axis1/control_word"/>
      <command_interface name="axis1/mode_of_operation"/>
      <state_interface name="axis1/internal_position"/>
      <state_interface name="axis1/position"/>
      <state_interface name="axis1/velocity"/>
      <state_interface name="axis1/effort"/>
      <state_interface name="axis1/status_word"/>
      <state_interface name="axis1/error_code"/>
      <state_interface name="axis1/force_x"/>
      <state_interface name="axis1/force_y"/>
      <state_interface name="axis1/force_z"/>
      <ec_module name="ec_module">
        <plugin>ethercat_generic_plugins/GenericEcSlave</plugin>
        <param name="alias">0</param>
        <param name="position">2</param>
        <param name="mode_of_operation">8</param>
        <param name="slave_config">/home/gene/aidin_dualarm_ws/install/aidin_hand_description/share/aidin_hand_description/config/welcon_slave.yaml</param>
      </ec_module>
    </joint>
    <joint name="left_middle_encoder2">
      <command_interface name="axis2/position"/>
      <command_interface name="axis2/velocity"/>
      <command_interface name="axis2/effort"/>
      <command_interface name="axis2/maximum_effort"/>
      <command_interface name="axis2/control_word"/>
      <command_interface name="axis2/mode_of_operation"/>
      <state_interface name="axis2/internal_position"/>
      <state_interface name="axis2/position"/>
      <state_interface name="axis2/velocity"/>
      <state_interface name="axis2/effort"/>
      <state_interface name="axis2/status_word"/>
      <state_interface name="axis2/error_code"/>
      <state_interface name="axis2/torque_x"/>
      <state_interface name="axis2/torque_y"/>
      <state_interface name="axis2/torque_z"/>
      <ec_module name="ec_module">
        <plugin>ethercat_generic_plugins/GenericEcSlave</plugin>
        <param name="alias">0</param>
        <param name="position">2</param>
        <param name="mode_of_operation">8</param>
        <param name="slave_config">/home/gene/aidin_dualarm_ws/install/aidin_hand_description/share/aidin_hand_description/config/welcon_slave.yaml</param>
      </ec_module>
    </joint>
    <joint name="left_middle_encoder3">
      <command_interface name="axis3/position"/>
      <command_interface name="axis3/velocity"/>
      <command_interface name="axis3/effort"/>
      <command_interface name="axis3/maximum_effort"/>
      <command_interface name="axis3/control_word"/>
      <command_interface name="axis3/mode_of_operation"/>
      <state_interface name="axis3/internal_position"/>
      <state_interface name="axis3/position"/>
      <state_interface name="axis3/velocity"/>
      <state_interface name="axis3/effort"/>
      <state_interface name="axis3/status_word"/>
      <state_interface name="axis3/error_code"/>
      <ec_module name="ec_module">
        <plugin>ethercat_generic_plugins/GenericEcSlave</plugin>
        <param name="alias">0</param>
        <param name="position">2</param>
        <param name="mode_of_operation">8</param>
        <param name="slave_config">/home/gene/aidin_dualarm_ws/install/aidin_hand_description/share/aidin_hand_description/config/welcon_slave.yaml</param>
      </ec_module>
    </joint>
    <joint name="left_ring_encoder1">
      <command_interface name="axis1/position"/>
      <command_interface name="axis1/velocity"/>
      <command_interface name="axis1/effort"/>
      <command_interface name="axis1/maximum_effort"/>
      <command_interface name="axis1/control_word"/>
      <command_interface name="axis1/mode_of_operation"/>
      <state_interface name="axis1/internal_position"/>
      <state_interface name="axis1/position"/>
      <state_interface name="axis1/velocity"/>
      <state_interface name="axis1/effort"/>
      <state_interface name="axis1/status_word"/>
      <state_interface name="axis1/error_code"/>
      <state_interface name="axis1/force_x"/>
      <state_interface name="axis1/force_y"/>
      <state_interface name="axis1/force_z"/>
      <ec_module name="ec_module">
        <plugin>ethercat_generic_plugins/GenericEcSlave</plugin>
        <param name="alias">0</param>
        <param name="position">3</param>
        <param name="mode_of_operation">8</param>
        <param name="slave_config">/home/gene/aidin_dualarm_ws/install/aidin_hand_description/share/aidin_hand_description/config/welcon_slave.yaml</param>
      </ec_module>
    </joint>
    <joint name="left_ring_encoder2">
      <command_interface name="axis2/position"/>
      <command_interface name="axis2/velocity"/>
      <command_interface name="axis2/effort"/>
      <command_interface name="axis2/maximum_effort"/>
      <command_interface name="axis2/control_word"/>
      <command_interface name="axis2/mode_of_operation"/>
      <state_interface name="axis2/internal_position"/>
      <state_interface name="axis2/position"/>
      <state_interface name="axis2/velocity"/>
      <state_interface name="axis2/effort"/>
      <state_interface name="axis2/status_word"/>
      <state_interface name="axis2/error_code"/>
      <state_interface name="axis2/torque_x"/>
      <state_interface name="axis2/torque_y"/>
      <state_interface name="axis2/torque_z"/>
      <ec_module name="ec_module">
        <plugin>ethercat_generic_plugins/GenericEcSlave</plugin>
        <param name="alias">0</param>
        <param name="position">3</param>
        <param name="mode_of_operation">8</param>
        <param name="slave_config">/home/gene/aidin_dualarm_ws/install/aidin_hand_description/share/aidin_hand_description/config/welcon_slave.yaml</param>
      </ec_module>
    </joint>
    <joint name="left_ring_encoder3">
      <command_interface name="axis3/position"/>
      <command_interface name="axis3/velocity"/>
      <command_interface name="axis3/effort"/>
      <command_interface name="axis3/maximum_effort"/>
      <command_interface name="axis3/control_word"/>
      <command_interface name="axis3/mode_of_operation"/>
      <state_interface name="axis3/internal_position"/>
      <state_interface name="axis3/position"/>
      <state_interface name="axis3/velocity"/>
      <state_interface name="axis3/effort"/>
      <state_interface name="axis3/status_word"/>
      <state_interface name="axis3/error_code"/>
      <ec_module name="ec_module">
        <plugin>ethercat_generic_plugins/GenericEcSlave</plugin>
        <param name="alias">0</param>
        <param name="position">3</param>
        <param name="mode_of_operation">8</param>
        <param name="slave_config">/home/gene/aidin_dualarm_ws/install/aidin_hand_description/share/aidin_hand_description/config/welcon_slave.yaml</param>
      </ec_module>
    </joint>
    <joint name="left_baby_encoder1">
      <command_interface name="axis1/position"/>
      <command_interface name="axis1/velocity"/>
      <command_interface name="axis1/effort"/>
      <command_interface name="axis1/maximum_effort"/>
      <command_interface name="axis1/control_word"/>
      <command_interface name="axis1/mode_of_operation"/>
      <state_interface name="axis1/internal_position"/>
      <state_interface name="axis1/position"/>
      <state_interface name="axis1/velocity"/>
      <state_interface name="axis1/effort"/>
      <state_interface name="axis1/status_word"/>
      <state_interface name="axis1/error_code"/>
      <state_interface name="axis1/force_x"/>
      <state_interface name="axis1/force_y"/>
      <state_interface name="axis1/force_z"/>
      <ec_module name="ec_module">
        <plugin>ethercat_generic_plugins/GenericEcSlave</plugin>
        <param name="alias">0</param>
        <param name="position">4</param>
        <param name="mode_of_operation">8</param>
        <param name="slave_config">/home/gene/aidin_dualarm_ws/install/aidin_hand_description/share/aidin_hand_description/config/welcon_slave.yaml</param>
      </ec_module>
    </joint>
    <joint name="left_baby_encoder2">
      <command_interface name="axis2/position"/>
      <command_interface name="axis2/velocity"/>
      <command_interface name="axis2/effort"/>
      <command_interface name="axis2/maximum_effort"/>
      <command_interface name="axis2/control_word"/>
      <command_interface name="axis2/mode_of_operation"/>
      <state_interface name="axis2/internal_position"/>
      <state_interface name="axis2/position"/>
      <state_interface name="axis2/velocity"/>
      <state_interface name="axis2/effort"/>
      <state_interface name="axis2/status_word"/>
      <state_interface name="axis2/error_code"/>
      <state_interface name="axis2/torque_x"/>
      <state_interface name="axis2/torque_y"/>
      <state_interface name="axis2/torque_z"/>
      <ec_module name="ec_module">
        <plugin>ethercat_generic_plugins/GenericEcSlave</plugin>
        <param name="alias">0</param>
        <param name="position">4</param>
        <param name="mode_of_operation">8</param>
        <param name="slave_config">/home/gene/aidin_dualarm_ws/install/aidin_hand_description/share/aidin_hand_description/config/welcon_slave.yaml</param>
      </ec_module>
    </joint>
    <joint name="left_baby_encoder3">
      <command_interface name="axis3/position"/>
      <command_interface name="axis3/velocity"/>
      <command_interface name="axis3/effort"/>
      <command_interface name="axis3/maximum_effort"/>
      <command_interface name="axis3/control_word"/>
      <command_interface name="axis3/mode_of_operation"/>
      <state_interface name="axis3/internal_position"/>
      <state_interface name="axis3/position"/>
      <state_interface name="axis3/velocity"/>
      <state_interface name="axis3/effort"/>
      <state_interface name="axis3/status_word"/>
      <state_interface name="axis3/error_code"/>
      <ec_module name="ec_module">
        <plugin>ethercat_generic_plugins/GenericEcSlave</plugin>
        <param name="alias">0</param>
        <param name="position">4</param>
        <param name="mode_of_operation">8</param>
        <param name="slave_config">/home/gene/aidin_dualarm_ws/install/aidin_hand_description/share/aidin_hand_description/config/welcon_slave.yaml</param>
      </ec_module>
    </joint>
    <joint name="left_thumb_joint1">
      <state_interface name="position"/>
      <command_interface name="position"/>
    </joint>
    <joint name="left_thumb_joint2">
      <state_interface name="position"/>
      <command_interface name="position"/>
    </joint>
    <joint name="left_thumb_joint3">
      <state_interface name="position"/>
      <command_interface name="position"/>
    </joint>
    <joint name="left_index_joint1">
      <state_interface name="position"/>
      <command_interface name="position"/>
    </joint>
    <joint name="left_index_joint2">
      <state_interface name="position"/>
      <command_interface name="position"/>
    </joint>
    <joint name="left_index_joint3">
      <state_interface name="position"/>
      <command_interface name="position"/>
    </joint>
    <joint name="left_middle_joint1">
      <state_interface name="position"/>
      <command_interface name="position"/>
    </joint>
    <joint name="left_middle_joint2">
      <state_interface name="position"/>
      <command_interface name="position"/>
    </joint>
    <joint name="left_middle_joint3">
      <state_interface name="position"/>
      <command_interface name="position"/>
    </joint>
    <joint name="left_ring_joint1">
      <state_interface name="position"/>
      <command_interface name="position"/>
    </joint>
    <joint name="left_ring_joint2">
      <state_interface name="position"/>
      <command_interface name="position"/>
    </joint>
    <joint name="left_ring_joint3">
      <state_interface name="position"/>
      <command_interface name="position"/>
    </joint>
    <joint name="left_baby_joint1">
      <state_interface name="position"/>
      <command_interface name="position"/>
    </joint>
    <joint name="left_baby_joint2">
      <state_interface name="position"/>
      <command_interface name="position"/>
    </joint>
    <joint name="left_baby_joint3">
      <state_interface name="position"/>
      <command_interface name="position"/>
    </joint>
    <joint name="right_thumb_encoder1">
      <command_interface name="axis1/position"/>
      <command_interface name="axis1/velocity"/>
      <command_interface name="axis1/effort"/>
      <command_interface name="axis1/maximum_effort"/>
      <command_interface name="axis1/control_word"/>
      <command_interface name="axis1/mode_of_operation"/>
      <state_interface name="axis1/internal_position"/>
      <state_interface name="axis1/position"/>
      <state_interface name="axis1/velocity"/>
      <state_interface name="axis1/effort"/>
      <state_interface name="axis1/status_word"/>
      <state_interface name="axis1/error_code"/>
      <state_interface name="axis1/force_x"/>
      <state_interface name="axis1/force_y"/>
      <state_interface name="axis1/force_z"/>
      <ec_module name="ec_module">
        <plugin>ethercat_generic_plugins/GenericEcSlave</plugin>
        <param name="alias">0</param>
        <param name="position">5</param>
        <param name="mode_of_operation">8</param>
        <param name="slave_config">/home/gene/aidin_dualarm_ws/install/aidin_hand_description/share/aidin_hand_description/config/welcon_slave.yaml</param>
      </ec_module>
    </joint>
    <joint name="right_thumb_encoder2">
      <command_interface name="axis2/position"/>
      <command_interface name="axis2/velocity"/>
      <command_interface name="axis2/effort"/>
      <command_interface name="axis2/maximum_effort"/>
      <command_interface name="axis2/control_word"/>
      <command_interface name="axis2/mode_of_operation"/>
      <state_interface name="axis2/internal_position"/>
      <state_interface name="axis2/position"/>
      <state_interface name="axis2/velocity"/>
      <state_interface name="axis2/effort"/>
      <state_interface name="axis2/status_word"/>
      <state_interface name="axis2/error_code"/>
      <state_interface name="axis2/torque_x"/>
      <state_interface name="axis2/torque_y"/>
      <state_interface name="axis2/torque_z"/>
      <ec_module name="ec_module">
        <plugin>ethercat_generic_plugins/GenericEcSlave</plugin>
        <param name="alias">0</param>
        <param name="position">5</param>
        <param name="mode_of_operation">8</param>
        <param name="slave_config">/home/gene/aidin_dualarm_ws/install/aidin_hand_description/share/aidin_hand_description/config/welcon_slave.yaml</param>
      </ec_module>
    </joint>
    <joint name="right_thumb_encoder3">
      <command_interface name="axis3/position"/>
      <command_interface name="axis3/velocity"/>
      <command_interface name="axis3/effort"/>
      <command_interface name="axis3/maximum_effort"/>
      <command_interface name="axis3/control_word"/>
      <command_interface name="axis3/mode_of_operation"/>
      <state_interface name="axis3/internal_position"/>
      <state_interface name="axis3/position"/>
      <state_interface name="axis3/velocity"/>
      <state_interface name="axis3/effort"/>
      <state_interface name="axis3/status_word"/>
      <state_interface name="axis3/error_code"/>
      <ec_module name="ec_module">
        <plugin>ethercat_generic_plugins/GenericEcSlave</plugin>
        <param name="alias">0</param>
        <param name="position">5</param>
        <param name="mode_of_operation">8</param>
        <param name="slave_config">/home/gene/aidin_dualarm_ws/install/aidin_hand_description/share/aidin_hand_description/config/welcon_slave.yaml</param>
      </ec_module>
    </joint>
    <joint name="right_index_encoder1">
      <command_interface name="axis1/position"/>
      <command_interface name="axis1/velocity"/>
      <command_interface name="axis1/effort"/>
      <command_interface name="axis1/maximum_effort"/>
      <command_interface name="axis1/control_word"/>
      <command_interface name="axis1/mode_of_operation"/>
      <state_interface name="axis1/internal_position"/>
      <state_interface name="axis1/position"/>
      <state_interface name="axis1/velocity"/>
      <state_interface name="axis1/effort"/>
      <state_interface name="axis1/status_word"/>
      <state_interface name="axis1/error_code"/>
      <state_interface name="axis1/force_x"/>
      <state_interface name="axis1/force_y"/>
      <state_interface name="axis1/force_z"/>
      <ec_module name="ec_module">
        <plugin>ethercat_generic_plugins/GenericEcSlave</plugin>
        <param name="alias">0</param>
        <param name="position">6</param>
        <param name="mode_of_operation">8</param>
        <param name="slave_config">/home/gene/aidin_dualarm_ws/install/aidin_hand_description/share/aidin_hand_description/config/welcon_slave.yaml</param>
      </ec_module>
    </joint>
    <joint name="right_index_encoder2">
      <command_interface name="axis2/position"/>
      <command_interface name="axis2/velocity"/>
      <command_interface name="axis2/effort"/>
      <command_interface name="axis2/maximum_effort"/>
      <command_interface name="axis2/control_word"/>
      <command_interface name="axis2/mode_of_operation"/>
      <state_interface name="axis2/internal_position"/>
      <state_interface name="axis2/position"/>
      <state_interface name="axis2/velocity"/>
      <state_interface name="axis2/effort"/>
      <state_interface name="axis2/status_word"/>
      <state_interface name="axis2/error_code"/>
      <state_interface name="axis2/torque_x"/>
      <state_interface name="axis2/torque_y"/>
      <state_interface name="axis2/torque_z"/>
      <ec_module name="ec_module">
        <plugin>ethercat_generic_plugins/GenericEcSlave</plugin>
        <param name="alias">0</param>
        <param name="position">6</param>
        <param name="mode_of_operation">8</param>
        <param name="slave_config">/home/gene/aidin_dualarm_ws/install/aidin_hand_description/share/aidin_hand_description/config/welcon_slave.yaml</param>
      </ec_module>
    </joint>
    <joint name="right_index_encoder3">
      <command_interface name="axis3/position"/>
      <command_interface name="axis3/velocity"/>
      <command_interface name="axis3/effort"/>
      <command_interface name="axis3/maximum_effort"/>
      <command_interface name="axis3/control_word"/>
      <command_interface name="axis3/mode_of_operation"/>
      <state_interface name="axis3/internal_position"/>
      <state_interface name="axis3/position"/>
      <state_interface name="axis3/velocity"/>
      <state_interface name="axis3/effort"/>
      <state_interface name="axis3/status_word"/>
      <state_interface name="axis3/error_code"/>
      <ec_module name="ec_module">
        <plugin>ethercat_generic_plugins/GenericEcSlave</plugin>
        <param name="alias">0</param>
        <param name="position">6</param>
        <param name="mode_of_operation">8</param>
        <param name="slave_config">/home/gene/aidin_dualarm_ws/install/aidin_hand_description/share/aidin_hand_description/config/welcon_slave.yaml</param>
      </ec_module>
    </joint>
    <joint name="right_middle_encoder1">
      <command_interface name="axis1/position"/>
      <command_interface name="axis1/velocity"/>
      <command_interface name="axis1/effort"/>
      <command_interface name="axis1/maximum_effort"/>
      <command_interface name="axis1/control_word"/>
      <command_interface name="axis1/mode_of_operation"/>
      <state_interface name="axis1/internal_position"/>
      <state_interface name="axis1/position"/>
      <state_interface name="axis1/velocity"/>
      <state_interface name="axis1/effort"/>
      <state_interface name="axis1/status_word"/>
      <state_interface name="axis1/error_code"/>
      <state_interface name="axis1/force_x"/>
      <state_interface name="axis1/force_y"/>
      <state_interface name="axis1/force_z"/>
      <ec_module name="ec_module">
        <plugin>ethercat_generic_plugins/GenericEcSlave</plugin>
        <param name="alias">0</param>
        <param name="position">7</param>
        <param name="mode_of_operation">8</param>
        <param name="slave_config">/home/gene/aidin_dualarm_ws/install/aidin_hand_description/share/aidin_hand_description/config/welcon_slave.yaml</param>
      </ec_module>
    </joint>
    <joint name="right_middle_encoder2">
      <command_interface name="axis2/position"/>
      <command_interface name="axis2/velocity"/>
      <command_interface name="axis2/effort"/>
      <command_interface name="axis2/maximum_effort"/>
      <command_interface name="axis2/control_word"/>
      <command_interface name="axis2/mode_of_operation"/>
      <state_interface name="axis2/internal_position"/>
      <state_interface name="axis2/position"/>
      <state_interface name="axis2/velocity"/>
      <state_interface name="axis2/effort"/>
      <state_interface name="axis2/status_word"/>
      <state_interface name="axis2/error_code"/>
      <state_interface name="axis2/torque_x"/>
      <state_interface name="axis2/torque_y"/>
      <state_interface name="axis2/torque_z"/>
      <ec_module name="ec_module">
        <plugin>ethercat_generic_plugins/GenericEcSlave</plugin>
        <param name="alias">0</param>
        <param name="position">7</param>
        <param name="mode_of_operation">8</param>
        <param name="slave_config">/home/gene/aidin_dualarm_ws/install/aidin_hand_description/share/aidin_hand_description/config/welcon_slave.yaml</param>
      </ec_module>
    </joint>
    <joint name="right_middle_encoder3">
      <command_interface name="axis3/position"/>
      <command_interface name="axis3/velocity"/>
      <command_interface name="axis3/effort"/>
      <command_interface name="axis3/maximum_effort"/>
      <command_interface name="axis3/control_word"/>
      <command_interface name="axis3/mode_of_operation"/>
      <state_interface name="axis3/internal_position"/>
      <state_interface name="axis3/position"/>
      <state_interface name="axis3/velocity"/>
      <state_interface name="axis3/effort"/>
      <state_interface name="axis3/status_word"/>
      <state_interface name="axis3/error_code"/>
      <ec_module name="ec_module">
        <plugin>ethercat_generic_plugins/GenericEcSlave</plugin>
        <param name="alias">0</param>
        <param name="position">7</param>
        <param name="mode_of_operation">8</param>
        <param name="slave_config">/home/gene/aidin_dualarm_ws/install/aidin_hand_description/share/aidin_hand_description/config/welcon_slave.yaml</param>
      </ec_module>
    </joint>
    <joint name="right_ring_encoder1">
      <command_interface name="axis1/position"/>
      <command_interface name="axis1/velocity"/>
      <command_interface name="axis1/effort"/>
      <command_interface name="axis1/maximum_effort"/>
      <command_interface name="axis1/control_word"/>
      <command_interface name="axis1/mode_of_operation"/>
      <state_interface name="axis1/internal_position"/>
      <state_interface name="axis1/position"/>
      <state_interface name="axis1/velocity"/>
      <state_interface name="axis1/effort"/>
      <state_interface name="axis1/status_word"/>
      <state_interface name="axis1/error_code"/>
      <state_interface name="axis1/force_x"/>
      <state_interface name="axis1/force_y"/>
      <state_interface name="axis1/force_z"/>
      <ec_module name="ec_module">
        <plugin>ethercat_generic_plugins/GenericEcSlave</plugin>
        <param name="alias">0</param>
        <param name="position">8</param>
        <param name="mode_of_operation">8</param>
        <param name="slave_config">/home/gene/aidin_dualarm_ws/install/aidin_hand_description/share/aidin_hand_description/config/welcon_slave.yaml</param>
      </ec_module>
    </joint>
    <joint name="right_ring_encoder2">
      <command_interface name="axis2/position"/>
      <command_interface name="axis2/velocity"/>
      <command_interface name="axis2/effort"/>
      <command_interface name="axis2/maximum_effort"/>
      <command_interface name="axis2/control_word"/>
      <command_interface name="axis2/mode_of_operation"/>
      <state_interface name="axis2/internal_position"/>
      <state_interface name="axis2/position"/>
      <state_interface name="axis2/velocity"/>
      <state_interface name="axis2/effort"/>
      <state_interface name="axis2/status_word"/>
      <state_interface name="axis2/error_code"/>
      <state_interface name="axis2/torque_x"/>
      <state_interface name="axis2/torque_y"/>
      <state_interface name="axis2/torque_z"/>
      <ec_module name="ec_module">
        <plugin>ethercat_generic_plugins/GenericEcSlave</plugin>
        <param name="alias">0</param>
        <param name="position">8</param>
        <param name="mode_of_operation">8</param>
        <param name="slave_config">/home/gene/aidin_dualarm_ws/install/aidin_hand_description/share/aidin_hand_description/config/welcon_slave.yaml</param>
      </ec_module>
    </joint>
    <joint name="right_ring_encoder3">
      <command_interface name="axis3/position"/>
      <command_interface name="axis3/velocity"/>
      <command_interface name="axis3/effort"/>
      <command_interface name="axis3/maximum_effort"/>
      <command_interface name="axis3/control_word"/>
      <command_interface name="axis3/mode_of_operation"/>
      <state_interface name="axis3/internal_position"/>
      <state_interface name="axis3/position"/>
      <state_interface name="axis3/velocity"/>
      <state_interface name="axis3/effort"/>
      <state_interface name="axis3/status_word"/>
      <state_interface name="axis3/error_code"/>
      <ec_module name="ec_module">
        <plugin>ethercat_generic_plugins/GenericEcSlave</plugin>
        <param name="alias">0</param>
        <param name="position">8</param>
        <param name="mode_of_operation">8</param>
        <param name="slave_config">/home/gene/aidin_dualarm_ws/install/aidin_hand_description/share/aidin_hand_description/config/welcon_slave.yaml</param>
      </ec_module>
    </joint>
    <joint name="right_baby_encoder1">
      <command_interface name="axis1/position"/>
      <command_interface name="axis1/velocity"/>
      <command_interface name="axis1/effort"/>
      <command_interface name="axis1/maximum_effort"/>
      <command_interface name="axis1/control_word"/>
      <command_interface name="axis1/mode_of_operation"/>
      <state_interface name="axis1/internal_position"/>
      <state_interface name="axis1/position"/>
      <state_interface name="axis1/velocity"/>
      <state_interface name="axis1/effort"/>
      <state_interface name="axis1/status_word"/>
      <state_interface name="axis1/error_code"/>
      <state_interface name="axis1/force_x"/>
      <state_interface name="axis1/force_y"/>
      <state_interface name="axis1/force_z"/>
      <ec_module name="ec_module">
        <plugin>ethercat_generic_plugins/GenericEcSlave</plugin>
        <param name="alias">0</param>
        <param name="position">9</param>
        <param name="mode_of_operation">8</param>
        <param name="slave_config">/home/gene/aidin_dualarm_ws/install/aidin_hand_description/share/aidin_hand_description/config/welcon_slave.yaml</param>
      </ec_module>
    </joint>
    <joint name="right_baby_encoder2">
      <command_interface name="axis2/position"/>
      <command_interface name="axis2/velocity"/>
      <command_interface name="axis2/effort"/>
      <command_interface name="axis2/maximum_effort"/>
      <command_interface name="axis2/control_word"/>
      <command_interface name="axis2/mode_of_operation"/>
      <state_interface name="axis2/internal_position"/>
      <state_interface name="axis2/position"/>
      <state_interface name="axis2/velocity"/>
      <state_interface name="axis2/effort"/>
      <state_interface name="axis2/status_word"/>
      <state_interface name="axis2/error_code"/>
      <state_interface name="axis2/torque_x"/>
      <state_interface name="axis2/torque_y"/>
      <state_interface name="axis2/torque_z"/>
      <ec_module name="ec_module">
        <plugin>ethercat_generic_plugins/GenericEcSlave</plugin>
        <param name="alias">0</param>
        <param name="position">9</param>
        <param name="mode_of_operation">8</param>
        <param name="slave_config">/home/gene/aidin_dualarm_ws/install/aidin_hand_description/share/aidin_hand_description/config/welcon_slave.yaml</param>
      </ec_module>
    </joint>
    <joint name="right_baby_encoder3">
      <command_interface name="axis3/position"/>
      <command_interface name="axis3/velocity"/>
      <command_interface name="axis3/effort"/>
      <command_interface name="axis3/maximum_effort"/>
      <command_interface name="axis3/control_word"/>
      <command_interface name="axis3/mode_of_operation"/>
      <state_interface name="axis3/internal_position"/>
      <state_interface name="axis3/position"/>
      <state_interface name="axis3/velocity"/>
      <state_interface name="axis3/effort"/>
      <state_interface name="axis3/status_word"/>
      <state_interface name="axis3/error_code"/>
      <ec_module name="ec_module">
        <plugin>ethercat_generic_plugins/GenericEcSlave</plugin>
        <param name="alias">0</param>
        <param name="position">9</param>
        <param name="mode_of_operation">8</param>
        <param name="slave_config">/home/gene/aidin_dualarm_ws/install/aidin_hand_description/share/aidin_hand_description/config/welcon_slave.yaml</param>
      </ec_module>
    </joint>
    <joint name="right_thumb_joint1">
      <state_interface name="position"/>
      <command_interface name="position"/>
    </joint>
    <joint name="right_thumb_joint2">
      <state_interface name="position"/>
      <command_interface name="position"/>
    </joint>
    <joint name="right_thumb_joint3">
      <state_interface name="position"/>
      <command_interface name="position"/>
    </joint>
    <joint name="right_index_joint1">
      <state_interface name="position"/>
      <command_interface name="position"/>
    </joint>
    <joint name="right_index_joint2">
      <state_interface name="position"/>
      <command_interface name="position"/>
    </joint>
    <joint name="right_index_joint3">
      <state_interface name="position"/>
      <command_interface name="position"/>
    </joint>
    <joint name="right_middle_joint1">
      <state_interface name="position"/>
      <command_interface name="position"/>
    </joint>
    <joint name="right_middle_joint2">
      <state_interface name="position"/>
      <command_interface name="position"/>
    </joint>
    <joint name="right_middle_joint3">
      <state_interface name="position"/>
      <command_interface name="position"/>
    </joint>
    <joint name="right_ring_joint1">
      <state_interface name="position"/>
      <command_interface name="position"/>
    </joint>
    <joint name="right_ring_joint2">
      <state_interface name="position"/>
      <command_interface name="position"/>
    </joint>
    <joint name="right_ring_joint3">
      <state_interface name="position"/>
      <command_interface name="position"/>
    </joint>
    <joint name="right_baby_joint1">
      <state_interface name="position"/>
      <command_interface name="position"/>
    </joint>
    <joint name="right_baby_joint2">
      <state_interface name="position"/>
      <command_interface name="position"/>
    </joint>
    <joint name="right_baby_joint3">
      <state_interface name="position"/>
      <command_interface name="position"/>
    </joint>
  </ros2_control>
</robot>
